Workbook

Sheet 00 Start
A1: Lecture 07 | Worked Excel guide
A3: Use the small lecture examples first. Then estimate inputs from the embedded monthly dataset and reproduce the larger Solver exercises.
A5: Learning route
A6: 01 Factor Examples | B6: Reproduce Eta expected/realized returns and Theta alpha.
A7: 02 APT Solver | B7: Construct a scaled, zero-investment arbitrage.
A8: 03 Hedge Solver | B8: Choose the hedge and account for borrowing.
A9: 04 Prices | B9: Inspect the common stock-price snapshot.
A10: 05 Factors | B10: Keep factor definitions and return units explicit.
A11: 06 Returns | B11: Calculate stock total returns.
A12: 07 Excess | B12: Subtract RF from stocks.
A13: 08 CAPM | B13: Estimate a one-factor benchmark.
A14: 09 FF3 | B14: Estimate market, size and value exposures.
A15: 10 Carhart4 | B15: Add momentum.
A16: 11 FF5 | B16: Estimate the five-factor specification.
A17: 12 Model Comparison | B17: Compare alpha and fit.
... A22: 17 Mimic Solver | B22: Construct a factor-mimicking portfolio with explicit financing.
A24: Working with the workbook
A25: Gold = editable assumptions or Solver decisions; green = calculated results; gray = intermediate formulas. Source sheets contain the fixed historical snapshot.
A26: Use desktop Excel with Solver. Windows: File > Options > Add-ins > Manage Excel Add-ins > Go > Solver Add-in. Mac: Tools > Excel Add-ins > Solver Add-in.
A27: Every Solver exercise lists its objective, decisions, constraints and method. Worked solutions are saved; reset the decision cells to the stated starting values and solve again.
A28: Historical sample: 120 common monthly returns, January 2016 to December 2025. The 121 adjusted-price observations include December 2015.
A29: Historical optimization uses monthly excess-return means and covariances. Annualized mean = 12 times monthly mean; annualized volatility = SQRT(12) times monthly volatility. Small examples keep the original lecture period.
A30: Historical means are in-sample estimates for this exercise. Editable return assumptions are separate. A solved in-sample portfolio is not a forecast or evidence of future performance.
A31: All data and formulas are in this file. No internet, Python or macros are required. Solver settings are saved on each exercise sheet and also listed in its instructions.
A32: After changing prices, assumptions or constraints, formulas recalculate, but optimization weights and frontier examples must be solved again.
A34: Sources and data conventions
A35: Stocks: AMD, AMZN, F, JPM, NVDA, PFE, TGT, XOM, WMT, VZ. Regressions use the French market excess-return factor: FF3 for CAPM, FF3 and Carhart; FF5 for the five-factor model.
A36: Yahoo Finance via yfinance: daily auto_adjust=True Close; retain the final available trading observation per calendar month. Returns are calculated in Excel.
... A41: Solver reference: https://support.microsoft.com/en-us/excel/define-and-solve-a-problem-by-using-solver

Sheet 01 Factor Examples
A1: Factor inputs | expected returns, surprises and alpha
A2: Back to guide
A3: Lecture 7, Questions 4 and 5. Annual inputs in the Eta example and monthly inputs in the Theta example are kept separate.
A5: Eta: annual risk-free rate | B5: 0.03
A7: Factor | B7: Annual premium | C7: Eta loading | D7: Forecast | E7: Actual | F7: Surprise
A8: GDP growth | B8: 0.05 | C8: 1.2 | D8: 0.03 | E8: 0.01 | F8: =E8-D8 -> -0.02
A9: Inflation | B9: -0.01 | C9: 0.5 | D9: 0.02 | E9: 0.04 | F9: =E9-D9 -> 0.02
A12: Eta expected annual return | B12: =B5+SUMPRODUCT(B8:B9,C8:C9) -> 0.085
A13: Eta realized annual return | B13: =B12+SUMPRODUCT(C8:C9,F8:F9) -> 0.071
A15: Zero idiosyncratic surprise is assumed. Inflation has a negative expected premium but a positive realized surprise; these enter different calculations.
A18: Theta | monthly factor benchmark
A20: Series | B20: Monthly mean | C20: Theta loading
A21: Market excess return | B21: 0.006 | C21: 1.1
A22: SMB | B22: 0.002 | C22: -0.5
A23: HML | B23: 0.0035 | C23: 0.4
A25: Monthly RF | B25: 0.002
A26: Theta total return after fees | B26: 0.0075
A28: Benchmark excess return | B28: =SUMPRODUCT(B21:B23,C21:C23) -> 0.007
A29: Benchmark total return | B29: =B25+B28 -> 0.009
A30: Monthly alpha | B30: =B26-B29 -> -0.0015
A31: Arithmetic annualized alpha | B31: =12*B30 -> -0.018
A34: How to recreate this output in Excel
A35: 1. For Eta, multiply each premium by its loading and add RF. Expected return = 8.50%.
A36: 2. Surprise = actual - forecast. Add loading x surprise to expected return. Realized return = 7.10%.
A37: 3. For Theta, SUMPRODUCT of factor means and loadings gives benchmark excess return = 0.70%; total return = 0.90%.
A38: 4. Monthly alpha = Theta total return - benchmark total return = -0.15%; arithmetic annualized alpha = -1.80%.
A39: 5. Distinguish expected compensation, realized shocks and regression alpha before estimating historical inputs.

Sheet 02 APT Solver
A1: Delta, Epsilon and Zeta | an arbitrage trade
A2: Back to guide
A3: Lecture 7, Question 3. Delta and Epsilon have zero residual risk. Zeta is risk-free. Dollar positions are positive for purchases and negative for shorts or borrowing.
A7: Input | B7: Delta | C7: Epsilon | D7: Zeta
A8: Factor beta | B8: 1.5 | C8: 1 | D8: 0
A9: Expected one-year return | B9: 0.1 | C9: 0.09 | D9: 0.03
A10: Dollar positions | B10: -100 | C10: 150 | D10: -50
A12: Delta implied factor premium | B12: =(B9-D9)/B8 -> 0.046666667
A13: Epsilon implied factor premium | B13: =(C9-D9)/C8 -> 0.06
A14: Net initial investment | B14: =SUM(B10:D10) -> 0
A15: Dollar factor exposure | B15: =SUMPRODUCT(B10:D10,B8:D8) -> 0
A18: Certain one-year profit | B18: =SUMPRODUCT(B10:D10,B9:D9) -> 2
A22: How to recreate this output in Excel
A23: 1. Open Data > Solver. Set Objective: B18; choose Max.
A24: 2. By Changing Variable Cells: B10:D10. Gold cells are the decisions.
A25: 3. Add constraints: B14 = 0; B15 = 0; B10 = -100.
A26: 4. Select Simplex LP. Clear "Make Unconstrained Variables Non-Negative"; apply only the constraints listed above.
A27: 5. In Options, enable Automatic Scaling; set constraint precision to 0.000000001. Select Solve, then Keep Solver Solution.
A28: 6. Saved cells contain a worked solution. Reset the decisions to the starting values below to reproduce it. Rerun Solver after changing assumptions.
A29: 7. Starting positions: Delta -100, Epsilon +100, Zeta 0. Factor exposure is initially nonzero.
A30: 8. Fixing Delta at -100 sets the scale. Without a scale restriction, ideal arbitrage can be expanded without limit.
A31: 9. Check: short $100 Delta, buy $150 Epsilon, borrow $50. Profit = $2. Percentage return on zero net investment is undefined.

Sheet 03 Hedge Solver
A1: Iota and Kappa | financing a factor hedge
A2: Back to guide
A3: Lecture 7, Question 6. Retain $100 of Iota and finance Kappa by borrowing. The loan has zero market and interest-rate exposures.
A7: Input | B7: Iota | C7: Kappa | D7: Risk-free loan
A8: Market beta | B8: 1.1 | C8: 0.2 | D8: 0
A9: Interest-rate beta | B9: 1.8 | C9: -0.6 | D9: 0
A10: Dollar positions | B10: 100 | C10: 300 | D10: -300
A14: Net equity | B14: =SUM(B10:D10) -> 100
A15: Dollar interest-rate exposure | B15: =SUMPRODUCT(B10:D10,B9:D9) -> -1.7053026e-12
A16: Market beta on net equity | B16: =SUMPRODUCT(B10:D10,B8:D8)/B14 -> 1.7
A18: Kappa purchase amount | B18: =C10 -> 300
A22: How to recreate this output in Excel
A23: 1. Open Data > Solver. Set Objective: B18; choose Min.
A24: 2. By Changing Variable Cells: C10:D10. Gold cells are the decisions.
A25: 3. Add constraints: B14 = 100; B15 = 0; C10 >= 0; D10 <= 0.
A26: 4. Select Simplex LP. Clear "Make Unconstrained Variables Non-Negative"; apply only the constraints listed above.
A27: 5. In Options, enable Automatic Scaling; set constraint precision to 0.000000001. Select Solve, then Keep Solver Solution.
A28: 6. Saved cells contain a worked solution. Reset the decisions to the starting values below to reproduce it. Rerun Solver after changing assumptions.
A29: 7. Start at zero in C10:D10. B10 stays fixed at $100 and is excluded from the changing cells.
A30: 8. Equality constraints determine hedge and financing. Minimizing purchase amount provides a linear objective.
A31: 9. Check: Kappa $300; loan -$300; equity $100; market beta 1.70. Divide exposure by net equity, not gross assets of $400.

Sheet 04 Prices
A1: Monthly adjusted closing prices
A2: Back to guide
A3: Fixed observations. Adjusted stock prices incorporate splits and dividends; the market column is a total-return index.
A7: Month | B7: AMD | C7: AMZN | D7: F | E7: JPM | F7: NVDA | G7: PFE | H7: TGT | I7: XOM | J7: WMT | K7: VZ | L7: ^SP500TR
A8: 42369 | B8: 2.8699999 | C8: 33.794498 | D8: 7.8683395 | E8: 49.676094 | F8: 0.80210251 | G8: 18.921942 | H8: 52.515732 | I8: 49.312317 | J8: 16.922689 | K8: 26.117039 | L8: 3821.6001
A9: 42400 | B9: 2.2 | C9: 29.35 | D9: 6.8925858 | E9: 45.063694 | F9: 0.71279055 | G9: 17.872681 | H9: 52.378307 | I9: 49.249046 | J9: 18.319569 | K9: 28.583307 | L9: 3631.96
A10: 42429 | B10: 2.1400001 | C10: 27.625999 | D10: 7.2216291 | E10: 42.640091 | F10: 0.76594579 | G10: 17.566858 | H10: 57.21035 | I10: 51.164261 | J10: 18.314051 | K10: 29.018042 | L10: 3627.0601
A11: 42460 | B11: 2.8499999 | C11: 29.681999 | D11: 7.7931252 | E11: 44.851631 | F11: 0.87023759 | G11: 17.549095 | H11: 60.00341 | I11: 53.360184 | J11: 19.047558 | K11: 30.934269 | L11: 3873.1101
A12: 42490 | B12: 3.55 | C12: 32.9795 | D12: 7.9140983 | E12: 48.220348 | F12: 0.86779517 | G12: 19.366762 | H12: 57.976074 | I12: 56.430676 | J12: 18.597025 | K12: 29.445734 | L12: 3888.1299
A13: 42521 | B13: 4.5700002 | C13: 36.1395 | D13: 7.8732414 | E13: 49.799725 | F13: 1.144066 | G13: 20.728971 | H13: 50.541523 | I13: 57.304066 | J13: 19.828552 | K13: 29.422623 | L13: 3957.95
A14: 42551 | B14: 5.1399999 | C14: 35.780998 | D14: 7.336298 | E14: 47.411587 | F14: 1.1511675 | G14: 21.033642 | H14: 51.305729 | I14: 60.34243 | J14: 20.456066 | K14: 32.278175 | L14: 3968.21
A15: 42582 | B15: 6.8600001 | C15: 37.940498 | D15: 7.4698415 | E15: 49.187801 | F15: 1.398249 | G15: 22.037228 | H15: 55.354641 | I15: 57.259018 | J15: 20.442064 | K15: 32.352966 | L15: 4114.5098
A16: 42613 | B16: 7.4000001 | C16: 38.458 | D16: 7.4344387 | E16: 51.902092 | F16: 1.504845 | G16: 20.961523 | H16: 51.989098 | I16: 56.572212 | J16: 20.150442 | K16: 30.554611 | L16: 4120.29
A17: 42643 | B17: 6.9099998 | C17: 41.865501 | D17: 7.1217198 | E17: 51.202366 | F17: 1.6809908 | G17: 20.401346 | H17: 50.870659 | I17: 56.66309 | J17: 20.342247 | K17: 30.350258 | L17: 4121.0601
A18: 42674 | B18: 7.23 | C18: 39.491001 | D18: 7.0133085 | E18: 53.642521 | F18: 1.7457572 | G18: 19.100286 | H18: 50.907684 | I18: 54.092209 | J18: 19.749912 | K18: 28.405071 | L18: 4045.8899
A19: 42704 | B19: 8.9099998 | C19: 37.5285 | D19: 7.1447358 | E19: 62.092419 | F19: 2.2653153 | G19: 19.55237 | H19: 57.696152 | I19: 57.177933 | J19: 19.865562 | K19: 29.468044 | L19: 4195.73
... A128: 46022 | B128: 214.16 | C128: 230.82001 | D128: 12.680525 | E128: 317.70856 | F128: 186.06461 | G128: 23.67787 | H128: 95.129997 | I128: 117.97338 | J128: 110.70502 | K128: 38.781048 | L128: 15220.45

Sheet 05 Factors
A1: Monthly factor returns and risk-free return
A2: Back to guide
A3: FF3 and Carhart use C:F. FF5 uses G:K. RF is shared after checking both source files. Values are decimal returns.
A7: Month | B7: RF | C7: MKT (FF3) | D7: SMB (FF3) | E7: HML (FF3) | F7: MOM | G7: MKT (FF5) | H7: SMB (FF5) | I7: HML (FF5) | J7: RMW | K7: CMA
A8: 42400 | B8: 0.0001 | C8: -0.0574 | D8: -0.034 | E8: 0.0208 | F8: 0.0148 | G8: -0.0574 | H8: -0.0344 | I8: 0.0208 | J8: 0.0278 | K8: 0.0305
A9: 42429 | B9: 0.0002 | C9: -0.0006 | D9: 0.0073 | E9: -0.0061 | F9: -0.0436 | G9: -0.0007 | H9: 0.0087 | I9: -0.0061 | J9: 0.033 | K9: 0.0197
A10: 42460 | B10: 0.0002 | C10: 0.0695 | D10: 0.0075 | E10: 0.0123 | F10: -0.0504 | G10: 0.0695 | H10: 0.0101 | I10: 0.0123 | J10: 0.0068 | K10: 0.0006
A11: 42490 | B11: 0.0001 | C11: 0.0092 | D11: 0.0077 | E11: 0.0322 | F11: -0.0599 | G11: 0.0091 | H11: 0.0123 | I11: 0.0322 | J11: -0.0285 | K11: 0.0174
A12: 42521 | B12: 0.0001 | C12: 0.0178 | D12: -0.0018 | E12: -0.0162 | F12: 0.0139 | G12: 0.0178 | H12: -0.0062 | I12: -0.0162 | J12: -0.011 | K12: -0.0254
A13: 42551 | B13: 0.0002 | C13: -0.0003 | D13: 0.006 | E13: -0.0149 | F13: 0.0414 | G13: -0.0003 | H13: 0.0042 | I13: -0.0149 | J13: 0.0145 | K13: 0.019
A14: 42582 | B14: 0.0002 | C14: 0.0394 | D14: 0.0247 | E14: -0.0127 | F14: -0.0338 | G14: 0.0394 | H14: 0.0249 | I14: -0.0127 | J14: 0.0134 | K14: -0.0118
A15: 42613 | B15: 0.0002 | C15: 0.0049 | D15: 0.0119 | E15: 0.0317 | F15: -0.0346 | G15: 0.0049 | H15: 0.0168 | I15: 0.0317 | J15: -0.0184 | K15: -0.0039
A16: 42643 | B16: 0.0002 | C16: 0.0027 | D16: 0.0209 | E16: -0.0122 | F16: 0.0023 | G16: 0.0027 | H16: 0.0181 | I16: -0.0122 | J16: -0.0222 | K16: 0.0002
A17: 42674 | B17: 0.0002 | C17: -0.0201 | D17: -0.0441 | E17: 0.041 | F17: 0.0062 | G17: -0.0201 | H17: -0.0404 | I17: 0.041 | J17: 0.0096 | K17: 0.0028
A18: 42704 | B18: 0.0001 | C18: 0.0486 | D18: 0.056 | E18: 0.0832 | F18: -0.0474 | G18: 0.0485 | H18: 0.0697 | I18: 0.0832 | J18: -0.0017 | K18: 0.037
A19: 42735 | B19: 0.0003 | C19: 0.0181 | D19: 0.0013 | E19: 0.035 | F19: -0.0026 | G19: 0.0181 | H19: 0.0044 | I19: 0.035 | J19: 0.0126 | K19: -0.0032
... A127: 46022 | B127: 0.0034 | C127: -0.0036 | D127: -0.0104 | E127: 0.024 | F127: -0.024 | G127: -0.0036 | H127: -0.002 | I127: 0.024 | J127: 0.0032 | K127: 0.004

Sheet 06 Returns
A1: Monthly total returns
A2: Back to guide
A3: This month adjusted close / previous month adjusted close - 1. The December 2015 price produces the first monthly return.
A7: Month | B7: AMD | C7: AMZN | D7: F | E7: JPM | F7: NVDA | G7: PFE | H7: TGT | I7: XOM | J7: WMT | K7: VZ | L7: ^SP500TR
A8: ='04 Prices'!A9 -> 42400 | B8: ='04 Prices'!B9/'04 Prices'!B8-1 -> -0.23344943 | C8: ='04 Prices'!C9/'04 Prices'!C8-1 -> -0.13151543 | D8: ='04 Prices'!D9/'04 Prices'!D8-1 -> -0.12401013 | E8: ='04 Prices'!E9/'04 Prices'!E8-1 -> -0.092849491 | F8: ='04 Prices'!F9/'04 Prices'!F8-1 -> -0.11134731 | G8: ='04 Prices'!G9/'04 Prices'!G8-1 -> -0.055452083 | H8: ='04 Prices'!H9/'04 Prices'!H8-1 -> -0.0026168248 | I8: ='04 Prices'!I9/'04 Prices'!I8-1 -> -0.0012830581 | ... L8: ='04 Prices'!L9/'04 Prices'!L8-1 -> -0.049623229
A9: ='04 Prices'!A10 -> 42429 | B9: ='04 Prices'!B10/'04 Prices'!B9-1 -> -0.027272701 | C9: ='04 Prices'!C10/'04 Prices'!C9-1 -> -0.058739384 | D9: ='04 Prices'!D10/'04 Prices'!D9-1 -> 0.047738744 | E9: ='04 Prices'!E10/'04 Prices'!E9-1 -> -0.053781722 | F9: ='04 Prices'!F10/'04 Prices'!F9-1 -> 0.07457344 | G9: ='04 Prices'!G10/'04 Prices'!G9-1 -> -0.017111164 | H9: ='04 Prices'!H10/'04 Prices'!H9-1 -> 0.092252746 | I9: ='04 Prices'!I10/'04 Prices'!I9-1 -> 0.038888358 | ... L9: ='04 Prices'!L10/'04 Prices'!L9-1 -> -0.0013491069
A10: ='04 Prices'!A11 -> 42460 | B10: ='04 Prices'!B11/'04 Prices'!B10-1 -> 0.33177559 | C10: ='04 Prices'!C11/'04 Prices'!C10-1 -> 0.074422638 | D10: ='04 Prices'!D11/'04 Prices'!D10-1 -> 0.079136715 | E10: ='04 Prices'!E11/'04 Prices'!E10-1 -> 0.051865279 | F10: ='04 Prices'!F11/'04 Prices'!F10-1 -> 0.13616081 | G10: ='04 Prices'!G11/'04 Prices'!G10-1 -> -0.0010111733 | H10: ='04 Prices'!H11/'04 Prices'!H10-1 -> 0.048820892 | I10: ='04 Prices'!I11/'04 Prices'!I10-1 -> 0.042919077 | ... L10: ='04 Prices'!L11/'04 Prices'!L10-1 -> 0.067837324
A11: ='04 Prices'!A12 -> 42490 | B11: ='04 Prices'!B12/'04 Prices'!B11-1 -> 0.24561406 | C11: ='04 Prices'!C12/'04 Prices'!C11-1 -> 0.11109429 | D11: ='04 Prices'!D12/'04 Prices'!D11-1 -> 0.015523055 | E11: ='04 Prices'!E12/'04 Prices'!E11-1 -> 0.07510802 | F11: ='04 Prices'!F12/'04 Prices'!F11-1 -> -0.0028066123 | G11: ='04 Prices'!G12/'04 Prices'!G11-1 -> 0.10357611 | H11: ='04 Prices'!H12/'04 Prices'!H11-1 -> -0.033787015 | I11: ='04 Prices'!I12/'04 Prices'!I11-1 -> 0.057542751 | ... L11: ='04 Prices'!L12/'04 Prices'!L11-1 -> 0.0038779624
A12: ='04 Prices'!A13 -> 42521 | B12: ='04 Prices'!B13/'04 Prices'!B12-1 -> 0.28732401 | C12: ='04 Prices'!C13/'04 Prices'!C12-1 -> 0.095817094 | D12: ='04 Prices'!D13/'04 Prices'!D12-1 -> -0.0051625387 | E12: ='04 Prices'!E13/'04 Prices'!E12-1 -> 0.032753314 | F12: ='04 Prices'!F13/'04 Prices'!F12-1 -> 0.31835947 | G12: ='04 Prices'!G13/'04 Prices'!G12-1 -> 0.070337484 | H12: ='04 Prices'!H13/'04 Prices'!H12-1 -> -0.12823482 | I12: ='04 Prices'!I13/'04 Prices'!I12-1 -> 0.015477224 | ... L12: ='04 Prices'!L13/'04 Prices'!L12-1 -> 0.017957237
A13: ='04 Prices'!A14 -> 42551 | B13: ='04 Prices'!B14/'04 Prices'!B13-1 -> 0.12472641 | C13: ='04 Prices'!C14/'04 Prices'!C13-1 -> -0.0099199335 | D13: ='04 Prices'!D14/'04 Prices'!D13-1 -> -0.068198523 | E13: ='04 Prices'!E14/'04 Prices'!E13-1 -> -0.04795484 | F13: ='04 Prices'!F14/'04 Prices'!F13-1 -> 0.0062072782 | G13: ='04 Prices'!G14/'04 Prices'!G13-1 -> 0.014697803 | H13: ='04 Prices'!H14/'04 Prices'!H13-1 -> 0.015120358 | I13: ='04 Prices'!I14/'04 Prices'!I13-1 -> 0.053021795 | ... L13: ='04 Prices'!L14/'04 Prices'!L13-1 -> 0.0025922535
A14: ='04 Prices'!A15 -> 42582 | B14: ='04 Prices'!B15/'04 Prices'!B14-1 -> 0.33463041 | C14: ='04 Prices'!C15/'04 Prices'!C14-1 -> 0.060353267 | D14: ='04 Prices'!D15/'04 Prices'!D14-1 -> 0.018203117 | E14: ='04 Prices'!E15/'04 Prices'!E14-1 -> 0.037463724 | F14: ='04 Prices'!F15/'04 Prices'!F14-1 -> 0.21463559 | G14: ='04 Prices'!G15/'04 Prices'!G14-1 -> 0.047713364 | H14: ='04 Prices'!H15/'04 Prices'!H14-1 -> 0.078917348 | I14: ='04 Prices'!I15/'04 Prices'!I14-1 -> -0.051098575 | ... L14: ='04 Prices'!L15/'04 Prices'!L14-1 -> 0.03686796
A15: ='04 Prices'!A16 -> 42613 | B15: ='04 Prices'!B16/'04 Prices'!B15-1 -> 0.078717194 | C15: ='04 Prices'!C16/'04 Prices'!C15-1 -> 0.013639827 | D15: ='04 Prices'!D16/'04 Prices'!D15-1 -> -0.0047394279 | E15: ='04 Prices'!E16/'04 Prices'!E15-1 -> 0.05518219 | F15: ='04 Prices'!F16/'04 Prices'!F15-1 -> 0.076235342 | G15: ='04 Prices'!G16/'04 Prices'!G15-1 -> -0.048813063 | H15: ='04 Prices'!H16/'04 Prices'!H15-1 -> -0.06079966 | I15: ='04 Prices'!I16/'04 Prices'!I15-1 -> -0.011994717 | ... L15: ='04 Prices'!L16/'04 Prices'!L15-1 -> 0.0014048511
A16: ='04 Prices'!A17 -> 42643 | B16: ='04 Prices'!B17/'04 Prices'!B16-1 -> -0.066216249 | C16: ='04 Prices'!C17/'04 Prices'!C16-1 -> 0.088603183 | D16: ='04 Prices'!D17/'04 Prices'!D16-1 -> -0.042063548 | E16: ='04 Prices'!E17/'04 Prices'!E16-1 -> -0.013481655 | F16: ='04 Prices'!F17/'04 Prices'!F16-1 -> 0.11705245 | G16: ='04 Prices'!G17/'04 Prices'!G16-1 -> -0.026724053 | H16: ='04 Prices'!H17/'04 Prices'!H16-1 -> -0.021512947 | I16: ='04 Prices'!I17/'04 Prices'!I16-1 -> 0.0016063988 | ... L16: ='04 Prices'!L17/'04 Prices'!L16-1 -> 0.00018688479
A17: ='04 Prices'!A18 -> 42674 | B17: ='04 Prices'!B18/'04 Prices'!B17-1 -> 0.046309722 | C17: ='04 Prices'!C18/'04 Prices'!C17-1 -> -0.056717349 | D17: ='04 Prices'!D18/'04 Prices'!D17-1 -> -0.015222631 | E17: ='04 Prices'!E18/'04 Prices'!E17-1 -> 0.047657076 | F17: ='04 Prices'!F18/'04 Prices'!F17-1 -> 0.03852871 | G17: ='04 Prices'!G18/'04 Prices'!G17-1 -> -0.063773229 | H17: ='04 Prices'!H18/'04 Prices'!H17-1 -> 0.00072783511 | I17: ='04 Prices'!I18/'04 Prices'!I17-1 -> -0.04537135 | ... L17: ='04 Prices'!L18/'04 Prices'!L17-1 -> -0.018240493
A18: ='04 Prices'!A19 -> 42704 | B18: ='04 Prices'!B19/'04 Prices'!B18-1 -> 0.23236512 | C18: ='04 Prices'!C19/'04 Prices'!C18-1 -> -0.049694904 | D18: ='04 Prices'!D19/'04 Prices'!D18-1 -> 0.018739699 | E18: ='04 Prices'!E19/'04 Prices'!E18-1 -> 0.15752238 | F18: ='04 Prices'!F19/'04 Prices'!F18-1 -> 0.29761187 | G18: ='04 Prices'!G19/'04 Prices'!G18-1 -> 0.023668943 | H18: ='04 Prices'!H19/'04 Prices'!H18-1 -> 0.13334858 | I18: ='04 Prices'!I19/'04 Prices'!I18-1 -> 0.057045625 | ... L18: ='04 Prices'!L19/'04 Prices'!L18-1 -> 0.037035137
A19: ='04 Prices'!A20 -> 42735 | B19: ='04 Prices'!B20/'04 Prices'!B19-1 -> 0.27272731 | C19: ='04 Prices'!C20/'04 Prices'!C19-1 -> -0.00093262048 | D19: ='04 Prices'!D20/'04 Prices'!D19-1 -> 0.01421381 | E19: ='04 Prices'!E20/'04 Prices'!E19-1 -> 0.076337603 | F19: ='04 Prices'!F20/'04 Prices'!F19-1 -> 0.1577002 | G19: ='04 Prices'!G20/'04 Prices'!G19-1 -> 0.010578697 | H19: ='04 Prices'!H20/'04 Prices'!H19-1 -> -0.06486284 | I19: ='04 Prices'!I20/'04 Prices'!I19-1 -> 0.033906066 | ... L19: ='04 Prices'!L20/'04 Prices'!L19-1 -> 0.019765375
... A127: ='04 Prices'!A128 -> 46022 | B127: ='04 Prices'!B128/'04 Prices'!B127-1 -> -0.015492094 | C127: ='04 Prices'!C128/'04 Prices'!C127-1 -> -0.010290686 | D127: ='04 Prices'!D128/'04 Prices'!D127-1 -> -0.012048166 | E127: ='04 Prices'!E128/'04 Prices'!E127-1 -> 0.029193899 | F127: ='04 Prices'!F128/'04 Prices'!F127-1 -> 0.053730906 | G127: ='04 Prices'!G128/'04 Prices'!G127-1 -> -0.032634009 | H127: ='04 Prices'!H128/'04 Prices'!H127-1 -> 0.078680231 | I127: ='04 Prices'!I128/'04 Prices'!I127-1 -> 0.03812982 | ... L127: ='04 Prices'!L128/'04 Prices'!L127-1 -> 0.0006120874
A131: How to recreate this output in Excel
A132: 1. In B8 enter ='04 Prices'!B9/'04 Prices'!B8-1. Copy across to L8 and down to row 127.
A133: 2. Column L is the S&P 500 total-return index return; it is distinct from the French broad-market factor.

Sheet 07 Excess
A1: Monthly excess returns
A2: Back to guide
A3: Subtract matching monthly RF from stock and S&P 500 total returns. French MKT and long-short factors are already factor returns; do not subtract RF from them.
A7: Month | B7: AMD | C7: AMZN | D7: F | E7: JPM | F7: NVDA | G7: PFE | H7: TGT | I7: XOM | J7: WMT | K7: VZ | L7: ^SP500TR
A8: ='06 Returns'!A8 -> 42400 | B8: ='06 Returns'!B8-'05 Factors'!$B8 -> -0.23354943 | C8: ='06 Returns'!C8-'05 Factors'!$B8 -> -0.13161543 | D8: ='06 Returns'!D8-'05 Factors'!$B8 -> -0.12411013 | E8: ='06 Returns'!E8-'05 Factors'!$B8 -> -0.092949491 | F8: ='06 Returns'!F8-'05 Factors'!$B8 -> -0.11144731 | G8: ='06 Returns'!G8-'05 Factors'!$B8 -> -0.055552083 | H8: ='06 Returns'!H8-'05 Factors'!$B8 -> -0.0027168248 | I8: ='06 Returns'!I8-'05 Factors'!$B8 -> -0.0013830581 | ... L8: ='06 Returns'!L8-'05 Factors'!$B8 -> -0.049723229
A9: ='06 Returns'!A9 -> 42429 | B9: ='06 Returns'!B9-'05 Factors'!$B9 -> -0.027472701 | C9: ='06 Returns'!C9-'05 Factors'!$B9 -> -0.058939384 | D9: ='06 Returns'!D9-'05 Factors'!$B9 -> 0.047538744 | E9: ='06 Returns'!E9-'05 Factors'!$B9 -> -0.053981722 | F9: ='06 Returns'!F9-'05 Factors'!$B9 -> 0.07437344 | G9: ='06 Returns'!G9-'05 Factors'!$B9 -> -0.017311164 | H9: ='06 Returns'!H9-'05 Factors'!$B9 -> 0.092052746 | I9: ='06 Returns'!I9-'05 Factors'!$B9 -> 0.038688358 | ... L9: ='06 Returns'!L9-'05 Factors'!$B9 -> -0.0015491069
A10: ='06 Returns'!A10 -> 42460 | B10: ='06 Returns'!B10-'05 Factors'!$B10 -> 0.33157559 | C10: ='06 Returns'!C10-'05 Factors'!$B10 -> 0.074222638 | D10: ='06 Returns'!D10-'05 Factors'!$B10 -> 0.078936715 | E10: ='06 Returns'!E10-'05 Factors'!$B10 -> 0.051665279 | F10: ='06 Returns'!F10-'05 Factors'!$B10 -> 0.13596081 | G10: ='06 Returns'!G10-'05 Factors'!$B10 -> -0.0012111733 | H10: ='06 Returns'!H10-'05 Factors'!$B10 -> 0.048620892 | I10: ='06 Returns'!I10-'05 Factors'!$B10 -> 0.042719077 | ... L10: ='06 Returns'!L10-'05 Factors'!$B10 -> 0.067637324
A11: ='06 Returns'!A11 -> 42490 | B11: ='06 Returns'!B11-'05 Factors'!$B11 -> 0.24551406 | C11: ='06 Returns'!C11-'05 Factors'!$B11 -> 0.11099429 | D11: ='06 Returns'!D11-'05 Factors'!$B11 -> 0.015423055 | E11: ='06 Returns'!E11-'05 Factors'!$B11 -> 0.07500802 | F11: ='06 Returns'!F11-'05 Factors'!$B11 -> -0.0029066123 | G11: ='06 Returns'!G11-'05 Factors'!$B11 -> 0.10347611 | H11: ='06 Returns'!H11-'05 Factors'!$B11 -> -0.033887015 | I11: ='06 Returns'!I11-'05 Factors'!$B11 -> 0.057442751 | ... L11: ='06 Returns'!L11-'05 Factors'!$B11 -> 0.0037779624
A12: ='06 Returns'!A12 -> 42521 | B12: ='06 Returns'!B12-'05 Factors'!$B12 -> 0.28722401 | C12: ='06 Returns'!C12-'05 Factors'!$B12 -> 0.095717094 | D12: ='06 Returns'!D12-'05 Factors'!$B12 -> -0.0052625387 | E12: ='06 Returns'!E12-'05 Factors'!$B12 -> 0.032653314 | F12: ='06 Returns'!F12-'05 Factors'!$B12 -> 0.31825947 | G12: ='06 Returns'!G12-'05 Factors'!$B12 -> 0.070237484 | H12: ='06 Returns'!H12-'05 Factors'!$B12 -> -0.12833482 | I12: ='06 Returns'!I12-'05 Factors'!$B12 -> 0.015377224 | ... L12: ='06 Returns'!L12-'05 Factors'!$B12 -> 0.017857237
A13: ='06 Returns'!A13 -> 42551 | B13: ='06 Returns'!B13-'05 Factors'!$B13 -> 0.12452641 | C13: ='06 Returns'!C13-'05 Factors'!$B13 -> -0.010119934 | D13: ='06 Returns'!D13-'05 Factors'!$B13 -> -0.068398523 | E13: ='06 Returns'!E13-'05 Factors'!$B13 -> -0.04815484 | F13: ='06 Returns'!F13-'05 Factors'!$B13 -> 0.0060072782 | G13: ='06 Returns'!G13-'05 Factors'!$B13 -> 0.014497803 | H13: ='06 Returns'!H13-'05 Factors'!$B13 -> 0.014920358 | I13: ='06 Returns'!I13-'05 Factors'!$B13 -> 0.052821795 | ... L13: ='06 Returns'!L13-'05 Factors'!$B13 -> 0.0023922535
A14: ='06 Returns'!A14 -> 42582 | B14: ='06 Returns'!B14-'05 Factors'!$B14 -> 0.33443041 | C14: ='06 Returns'!C14-'05 Factors'!$B14 -> 0.060153267 | D14: ='06 Returns'!D14-'05 Factors'!$B14 -> 0.018003117 | E14: ='06 Returns'!E14-'05 Factors'!$B14 -> 0.037263724 | F14: ='06 Returns'!F14-'05 Factors'!$B14 -> 0.21443559 | G14: ='06 Returns'!G14-'05 Factors'!$B14 -> 0.047513364 | H14: ='06 Returns'!H14-'05 Factors'!$B14 -> 0.078717348 | I14: ='06 Returns'!I14-'05 Factors'!$B14 -> -0.051298575 | ... L14: ='06 Returns'!L14-'05 Factors'!$B14 -> 0.03666796
A15: ='06 Returns'!A15 -> 42613 | B15: ='06 Returns'!B15-'05 Factors'!$B15 -> 0.078517194 | C15: ='06 Returns'!C15-'05 Factors'!$B15 -> 0.013439827 | D15: ='06 Returns'!D15-'05 Factors'!$B15 -> -0.0049394279 | E15: ='06 Returns'!E15-'05 Factors'!$B15 -> 0.05498219 | F15: ='06 Returns'!F15-'05 Factors'!$B15 -> 0.076035342 | G15: ='06 Returns'!G15-'05 Factors'!$B15 -> -0.049013063 | H15: ='06 Returns'!H15-'05 Factors'!$B15 -> -0.06099966 | I15: ='06 Returns'!I15-'05 Factors'!$B15 -> -0.012194717 | ... L15: ='06 Returns'!L15-'05 Factors'!$B15 -> 0.0012048511
A16: ='06 Returns'!A16 -> 42643 | B16: ='06 Returns'!B16-'05 Factors'!$B16 -> -0.066416249 | C16: ='06 Returns'!C16-'05 Factors'!$B16 -> 0.088403183 | D16: ='06 Returns'!D16-'05 Factors'!$B16 -> -0.042263548 | E16: ='06 Returns'!E16-'05 Factors'!$B16 -> -0.013681655 | F16: ='06 Returns'!F16-'05 Factors'!$B16 -> 0.11685245 | G16: ='06 Returns'!G16-'05 Factors'!$B16 -> -0.026924053 | H16: ='06 Returns'!H16-'05 Factors'!$B16 -> -0.021712947 | I16: ='06 Returns'!I16-'05 Factors'!$B16 -> 0.0014063988 | ... L16: ='06 Returns'!L16-'05 Factors'!$B16 -> -1.3115212e-05
A17: ='06 Returns'!A17 -> 42674 | B17: ='06 Returns'!B17-'05 Factors'!$B17 -> 0.046109722 | C17: ='06 Returns'!C17-'05 Factors'!$B17 -> -0.056917349 | D17: ='06 Returns'!D17-'05 Factors'!$B17 -> -0.015422631 | E17: ='06 Returns'!E17-'05 Factors'!$B17 -> 0.047457076 | F17: ='06 Returns'!F17-'05 Factors'!$B17 -> 0.03832871 | G17: ='06 Returns'!G17-'05 Factors'!$B17 -> -0.063973229 | H17: ='06 Returns'!H17-'05 Factors'!$B17 -> 0.00052783511 | I17: ='06 Returns'!I17-'05 Factors'!$B17 -> -0.04557135 | ... L17: ='06 Returns'!L17-'05 Factors'!$B17 -> -0.018440493
A18: ='06 Returns'!A18 -> 42704 | B18: ='06 Returns'!B18-'05 Factors'!$B18 -> 0.23226512 | C18: ='06 Returns'!C18-'05 Factors'!$B18 -> -0.049794904 | D18: ='06 Returns'!D18-'05 Factors'!$B18 -> 0.018639699 | E18: ='06 Returns'!E18-'05 Factors'!$B18 -> 0.15742238 | F18: ='06 Returns'!F18-'05 Factors'!$B18 -> 0.29751187 | G18: ='06 Returns'!G18-'05 Factors'!$B18 -> 0.023568943 | H18: ='06 Returns'!H18-'05 Factors'!$B18 -> 0.13324858 | I18: ='06 Returns'!I18-'05 Factors'!$B18 -> 0.056945625 | ... L18: ='06 Returns'!L18-'05 Factors'!$B18 -> 0.036935137
A19: ='06 Returns'!A19 -> 42735 | B19: ='06 Returns'!B19-'05 Factors'!$B19 -> 0.27242731 | C19: ='06 Returns'!C19-'05 Factors'!$B19 -> -0.0012326205 | D19: ='06 Returns'!D19-'05 Factors'!$B19 -> 0.01391381 | E19: ='06 Returns'!E19-'05 Factors'!$B19 -> 0.076037603 | F19: ='06 Returns'!F19-'05 Factors'!$B19 -> 0.1574002 | G19: ='06 Returns'!G19-'05 Factors'!$B19 -> 0.010278697 | H19: ='06 Returns'!H19-'05 Factors'!$B19 -> -0.06516284 | I19: ='06 Returns'!I19-'05 Factors'!$B19 -> 0.033606066 | ... L19: ='06 Returns'!L19-'05 Factors'!$B19 -> 0.019465375
... A127: ='06 Returns'!A127 -> 46022 | B127: ='06 Returns'!B127-'05 Factors'!$B127 -> -0.018892094 | C127: ='06 Returns'!C127-'05 Factors'!$B127 -> -0.013690686 | D127: ='06 Returns'!D127-'05 Factors'!$B127 -> -0.015448166 | E127: ='06 Returns'!E127-'05 Factors'!$B127 -> 0.025793899 | F127: ='06 Returns'!F127-'05 Factors'!$B127 -> 0.050330906 | G127: ='06 Returns'!G127-'05 Factors'!$B127 -> -0.036034009 | H127: ='06 Returns'!H127-'05 Factors'!$B127 -> 0.075280231 | I127: ='06 Returns'!I127-'05 Factors'!$B127 -> 0.03472982 | ... L127: ='06 Returns'!L127-'05 Factors'!$B127 -> -0.0027879126
A131: How to recreate this output in Excel
A132: 1. In B8 enter ='06 Returns'!B8-'05 Factors'!$B8. Copy across to L8 and down to row 127.
A133: 2. Use these excess returns consistently for regressions and risk estimates. All assets have 120 observations.

Sheet 08 CAPM
A1: CAPM | one market factor
A2: Back to guide
A3: Same 120 monthly observations for every asset. LINEST includes an intercept. Alpha and its standard error are monthly.
A7: Asset | B7: Monthly alpha | C7: MKT | D7: R-squared | E7: Residual variance | F7: N | G7: Alpha SE
A8: AMD | B8: =INDEX(LINEST('07 Excess'!B$8:B$127,'05 Factors'!C$8:C$127,TRUE,TRUE),1,2) -> 0.026214739 | C8: =INDEX(LINEST('07 Excess'!B$8:B$127,'05 Factors'!C$8:C$127,TRUE,TRUE),1,1) -> 2.0435956 | D8: =INDEX(LINEST('07 Excess'!B$8:B$127,'05 Factors'!C$8:C$127,TRUE,TRUE),3,1) -> 0.29982822 | E8: =INDEX(LINEST('07 Excess'!B$8:B$127,'05 Factors'!C$8:C$127,TRUE,TRUE),5,2)/INDEX(LINEST('07 Excess'!B$8:B$127,'05 Factors'!C$8:C$127,TRUE,TRUE),4,2) -> 0.020298776 | F8: =COUNT('07 Excess'!B$8:B$127) -> 120 | G8: =INDEX(LINEST('07 Excess'!B$8:B$127,'05 Factors'!C$8:C$127,TRUE,TRUE),2,2) -> 0.013370988
A9: AMZN | B9: =INDEX(LINEST('07 Excess'!C$8:C$127,'05 Factors'!C$8:C$127,TRUE,TRUE),1,2) -> 0.0045510006 | C9: =INDEX(LINEST('07 Excess'!C$8:C$127,'05 Factors'!C$8:C$127,TRUE,TRUE),1,1) -> 1.2494013 | D9: =INDEX(LINEST('07 Excess'!C$8:C$127,'05 Factors'!C$8:C$127,TRUE,TRUE),3,1) -> 0.43200999 | E9: =INDEX(LINEST('07 Excess'!C$8:C$127,'05 Factors'!C$8:C$127,TRUE,TRUE),5,2)/INDEX(LINEST('07 Excess'!C$8:C$127,'05 Factors'!C$8:C$127,TRUE,TRUE),4,2) -> 0.0042716792 | F9: =COUNT('07 Excess'!C$8:C$127) -> 120 | G9: =INDEX(LINEST('07 Excess'!C$8:C$127,'05 Factors'!C$8:C$127,TRUE,TRUE),2,2) -> 0.0061337756
A10: F | B10: =INDEX(LINEST('07 Excess'!D$8:D$127,'05 Factors'!C$8:C$127,TRUE,TRUE),1,2) -> -0.0077380799 | C10: =INDEX(LINEST('07 Excess'!D$8:D$127,'05 Factors'!C$8:C$127,TRUE,TRUE),1,1) -> 1.411935 | D10: =INDEX(LINEST('07 Excess'!D$8:D$127,'05 Factors'!C$8:C$127,TRUE,TRUE),3,1) -> 0.3906082 | E10: =INDEX(LINEST('07 Excess'!D$8:D$127,'05 Factors'!C$8:C$127,TRUE,TRUE),5,2)/INDEX(LINEST('07 Excess'!D$8:D$127,'05 Factors'!C$8:C$127,TRUE,TRUE),4,2) -> 0.0064734012 | F10: =COUNT('07 Excess'!D$8:D$127) -> 120 | G10: =INDEX(LINEST('07 Excess'!D$8:D$127,'05 Factors'!C$8:C$127,TRUE,TRUE),2,2) -> 0.0075508324
A11: JPM | B11: =INDEX(LINEST('07 Excess'!E$8:E$127,'05 Factors'!C$8:C$127,TRUE,TRUE),1,2) -> 0.004083857 | C11: =INDEX(LINEST('07 Excess'!E$8:E$127,'05 Factors'!C$8:C$127,TRUE,TRUE),1,1) -> 1.1298104 | D11: =INDEX(LINEST('07 Excess'!E$8:E$127,'05 Factors'!C$8:C$127,TRUE,TRUE),3,1) -> 0.53731143 | E11: =INDEX(LINEST('07 Excess'!E$8:E$127,'05 Factors'!C$8:C$127,TRUE,TRUE),5,2)/INDEX(LINEST('07 Excess'!E$8:E$127,'05 Factors'!C$8:C$127,TRUE,TRUE),4,2) -> 0.0022878191 | F11: =COUNT('07 Excess'!E$8:E$127) -> 120 | G11: =INDEX(LINEST('07 Excess'!E$8:E$127,'05 Factors'!C$8:C$127,TRUE,TRUE),2,2) -> 0.0044888946
A12: NVDA | B12: =INDEX(LINEST('07 Excess'!F$8:F$127,'05 Factors'!C$8:C$127,TRUE,TRUE),1,2) -> 0.034336039 | C12: =INDEX(LINEST('07 Excess'!F$8:F$127,'05 Factors'!C$8:C$127,TRUE,TRUE),1,1) -> 1.8007268 | D12: =INDEX(LINEST('07 Excess'!F$8:F$127,'05 Factors'!C$8:C$127,TRUE,TRUE),3,1) -> 0.35651824 | E12: =INDEX(LINEST('07 Excess'!F$8:F$127,'05 Factors'!C$8:C$127,TRUE,TRUE),5,2)/INDEX(LINEST('07 Excess'!F$8:F$127,'05 Factors'!C$8:C$127,TRUE,TRUE),4,2) -> 0.012181422 | F12: =COUNT('07 Excess'!F$8:F$127) -> 120 | G12: =INDEX(LINEST('07 Excess'!F$8:F$127,'05 Factors'!C$8:C$127,TRUE,TRUE),2,2) -> 0.010358039
A13: PFE | B13: =INDEX(LINEST('07 Excess'!G$8:G$127,'05 Factors'!C$8:C$127,TRUE,TRUE),1,2) -> -0.0036443402 | C13: =INDEX(LINEST('07 Excess'!G$8:G$127,'05 Factors'!C$8:C$127,TRUE,TRUE),1,1) -> 0.53846744 | D13: =INDEX(LINEST('07 Excess'!G$8:G$127,'05 Factors'!C$8:C$127,TRUE,TRUE),3,1) -> 0.14019325 | E13: =INDEX(LINEST('07 Excess'!G$8:G$127,'05 Factors'!C$8:C$127,TRUE,TRUE),5,2)/INDEX(LINEST('07 Excess'!G$8:G$127,'05 Factors'!C$8:C$127,TRUE,TRUE),4,2) -> 0.0037011825 | F13: =COUNT('07 Excess'!G$8:G$127) -> 120 | G13: =INDEX(LINEST('07 Excess'!G$8:G$127,'05 Factors'!C$8:C$127,TRUE,TRUE),2,2) -> 0.0057095097
A14: TGT | B14: =INDEX(LINEST('07 Excess'!H$8:H$127,'05 Factors'!C$8:C$127,TRUE,TRUE),1,2) -> -0.0038504864 | C14: =INDEX(LINEST('07 Excess'!H$8:H$127,'05 Factors'!C$8:C$127,TRUE,TRUE),1,1) -> 1.0197782 | D14: =INDEX(LINEST('07 Excess'!H$8:H$127,'05 Factors'!C$8:C$127,TRUE,TRUE),3,1) -> 0.26929859 | E14: =INDEX(LINEST('07 Excess'!H$8:H$127,'05 Factors'!C$8:C$127,TRUE,TRUE),5,2)/INDEX(LINEST('07 Excess'!H$8:H$127,'05 Factors'!C$8:C$127,TRUE,TRUE),4,2) -> 0.0058730698 | F14: =COUNT('07 Excess'!H$8:H$127) -> 120 | G14: =INDEX(LINEST('07 Excess'!H$8:H$127,'05 Factors'!C$8:C$127,TRUE,TRUE),2,2) -> 0.0071921899
A15: XOM | B15: =INDEX(LINEST('07 Excess'!I$8:I$127,'05 Factors'!C$8:C$127,TRUE,TRUE),1,2) -> -0.00056273833 | C15: =INDEX(LINEST('07 Excess'!I$8:I$127,'05 Factors'!C$8:C$127,TRUE,TRUE),1,1) -> 0.84619421 | D15: =INDEX(LINEST('07 Excess'!I$8:I$127,'05 Factors'!C$8:C$127,TRUE,TRUE),3,1) -> 0.23954681 | E15: =INDEX(LINEST('07 Excess'!I$8:I$127,'05 Factors'!C$8:C$127,TRUE,TRUE),5,2)/INDEX(LINEST('07 Excess'!I$8:I$127,'05 Factors'!C$8:C$127,TRUE,TRUE),4,2) -> 0.0047311863 | F15: =COUNT('07 Excess'!I$8:I$127) -> 120 | G15: =INDEX(LINEST('07 Excess'!I$8:I$127,'05 Factors'!C$8:C$127,TRUE,TRUE),2,2) -> 0.0064552578
A16: WMT | B16: =INDEX(LINEST('07 Excess'!J$8:J$127,'05 Factors'!C$8:C$127,TRUE,TRUE),1,2) -> 0.010148405 | C16: =INDEX(LINEST('07 Excess'!J$8:J$127,'05 Factors'!C$8:C$127,TRUE,TRUE),1,1) -> 0.49034543 | D16: =INDEX(LINEST('07 Excess'!J$8:J$127,'05 Factors'!C$8:C$127,TRUE,TRUE),3,1) -> 0.17587425 | E16: =INDEX(LINEST('07 Excess'!J$8:J$127,'05 Factors'!C$8:C$127,TRUE,TRUE),5,2)/INDEX(LINEST('07 Excess'!J$8:J$127,'05 Factors'!C$8:C$127,TRUE,TRUE),4,2) -> 0.0023450027 | F16: =COUNT('07 Excess'!J$8:J$127) -> 120 | G16: =INDEX(LINEST('07 Excess'!J$8:J$127,'05 Factors'!C$8:C$127,TRUE,TRUE),2,2) -> 0.0045446478
A17: VZ | B17: =INDEX(LINEST('07 Excess'!K$8:K$127,'05 Factors'!C$8:C$127,TRUE,TRUE),1,2) -> -0.00059161138 | C17: =INDEX(LINEST('07 Excess'!K$8:K$127,'05 Factors'!C$8:C$127,TRUE,TRUE),1,1) -> 0.32310944 | D17: =INDEX(LINEST('07 Excess'!K$8:K$127,'05 Factors'!C$8:C$127,TRUE,TRUE),3,1) -> 0.079947158 | E17: =INDEX(LINEST('07 Excess'!K$8:K$127,'05 Factors'!C$8:C$127,TRUE,TRUE),5,2)/INDEX(LINEST('07 Excess'!K$8:K$127,'05 Factors'!C$8:C$127,TRUE,TRUE),4,2) -> 0.0025006728 | F17: =COUNT('07 Excess'!K$8:K$127) -> 120 | G17: =INDEX(LINEST('07 Excess'!K$8:K$127,'05 Factors'!C$8:C$127,TRUE,TRUE),2,2) -> 0.0046930697
A21: How to recreate this output in Excel
A22: 1. Use stock excess returns on 07 Excess as Y and '05 Factors'!C8:C127 as X.
A23: 2. LINEST(Y,X,TRUE,TRUE) estimates 1 factor coefficients and an intercept. INDEX selects individual results, so use ordinary Enter.
A24: 3. LINEST returns slopes in reverse X-column order, followed by the intercept. This table restores the original factor order.
A25: 4. Alpha = INDEX(LINEST(Y,X,TRUE,TRUE),1,2). Its standard error is in row 2 of the LINEST result, in the same column.
A26: 5. Residual variance = residual sum of squares / degrees of freedom, or SSE/(N - number of factors - 1).
A27: 6. Alternative: Data > Data Analysis > Regression; select the same Y and X ranges and leave Constant is Zero unchecked.
A28: 7. Positive alpha alone does not establish skill. Compare model definitions and sampling uncertainty; Alpha SE measures that uncertainty.

Sheet 09 FF3
A1: Fama-French | three factors
A2: Back to guide
A3: Same 120 monthly observations for every asset. LINEST includes an intercept. Alpha and its standard error are monthly.
A7: Asset | B7: Monthly alpha | C7: MKT | D7: SMB | E7: HML | F7: R-squared | G7: Residual variance | H7: N | I7: Alpha SE
A8: AMD | B8: =INDEX(LINEST('07 Excess'!B$8:B$127,'05 Factors'!C$8:E$127,TRUE,TRUE),1,4) -> 0.024935629 | C8: =INDEX(LINEST('07 Excess'!B$8:B$127,'05 Factors'!C$8:E$127,TRUE,TRUE),1,3) -> 2.0920315 | D8: =INDEX(LINEST('07 Excess'!B$8:B$127,'05 Factors'!C$8:E$127,TRUE,TRUE),1,2) -> -0.19720562 | E8: =INDEX(LINEST('07 Excess'!B$8:B$127,'05 Factors'!C$8:E$127,TRUE,TRUE),1,1) -> -1.0142849 | F8: =INDEX(LINEST('07 Excess'!B$8:B$127,'05 Factors'!C$8:E$127,TRUE,TRUE),3,1) -> 0.35503186 | G8: =INDEX(LINEST('07 Excess'!B$8:B$127,'05 Factors'!C$8:E$127,TRUE,TRUE),5,2)/INDEX(LINEST('07 Excess'!B$8:B$127,'05 Factors'!C$8:E$127,TRUE,TRUE),4,2) -> 0.019020745 | H8: =COUNT('07 Excess'!B$8:B$127) -> 120 | I8: =INDEX(LINEST('07 Excess'!B$8:B$127,'05 Factors'!C$8:E$127,TRUE,TRUE),2,4) -> 0.013083289
A9: AMZN | B9: =INDEX(LINEST('07 Excess'!C$8:C$127,'05 Factors'!C$8:E$127,TRUE,TRUE),1,4) -> 0.0038911085 | C9: =INDEX(LINEST('07 Excess'!C$8:C$127,'05 Factors'!C$8:E$127,TRUE,TRUE),1,3) -> 1.2669866 | D9: =INDEX(LINEST('07 Excess'!C$8:C$127,'05 Factors'!C$8:E$127,TRUE,TRUE),1,2) -> -0.049390745 | E9: =INDEX(LINEST('07 Excess'!C$8:C$127,'05 Factors'!C$8:E$127,TRUE,TRUE),1,1) -> -0.93858831 | F9: =INDEX(LINEST('07 Excess'!C$8:C$127,'05 Factors'!C$8:E$127,TRUE,TRUE),3,1) -> 0.60844056 | G9: =INDEX(LINEST('07 Excess'!C$8:C$127,'05 Factors'!C$8:E$127,TRUE,TRUE),5,2)/INDEX(LINEST('07 Excess'!C$8:C$127,'05 Factors'!C$8:E$127,TRUE,TRUE),4,2) -> 0.0029955712 | H9: =COUNT('07 Excess'!C$8:C$127) -> 120 | I9: =INDEX(LINEST('07 Excess'!C$8:C$127,'05 Factors'!C$8:E$127,TRUE,TRUE),2,4) -> 0.0051920993
A10: F | B10: =INDEX(LINEST('07 Excess'!D$8:D$127,'05 Factors'!C$8:E$127,TRUE,TRUE),1,4) -> -0.0058614992 | C10: =INDEX(LINEST('07 Excess'!D$8:D$127,'05 Factors'!C$8:E$127,TRUE,TRUE),1,3) -> 1.3241554 | D10: =INDEX(LINEST('07 Excess'!D$8:D$127,'05 Factors'!C$8:E$127,TRUE,TRUE),1,2) -> 0.40754901 | E10: =INDEX(LINEST('07 Excess'!D$8:D$127,'05 Factors'!C$8:E$127,TRUE,TRUE),1,1) -> 0.55004242 | F10: =INDEX(LINEST('07 Excess'!D$8:D$127,'05 Factors'!C$8:E$127,TRUE,TRUE),3,1) -> 0.4476797 | G10: =INDEX(LINEST('07 Excess'!D$8:D$127,'05 Factors'!C$8:E$127,TRUE,TRUE),5,2)/INDEX(LINEST('07 Excess'!D$8:D$127,'05 Factors'!C$8:E$127,TRUE,TRUE),4,2) -> 0.0059683041 | H10: =COUNT('07 Excess'!D$8:D$127) -> 120 | I10: =INDEX(LINEST('07 Excess'!D$8:D$127,'05 Factors'!C$8:E$127,TRUE,TRUE),2,4) -> 0.0073287285
A11: JPM | B11: =INDEX(LINEST('07 Excess'!E$8:E$127,'05 Factors'!C$8:E$127,TRUE,TRUE),1,4) -> 0.0046692892 | C11: =INDEX(LINEST('07 Excess'!E$8:E$127,'05 Factors'!C$8:E$127,TRUE,TRUE),1,3) -> 1.114046 | D11: =INDEX(LINEST('07 Excess'!E$8:E$127,'05 Factors'!C$8:E$127,TRUE,TRUE),1,2) -> 0.044972839 | E11: =INDEX(LINEST('07 Excess'!E$8:E$127,'05 Factors'!C$8:E$127,TRUE,TRUE),1,1) -> 0.82351625 | F11: =INDEX(LINEST('07 Excess'!E$8:E$127,'05 Factors'!C$8:E$127,TRUE,TRUE),3,1) -> 0.74396265 | G11: =INDEX(LINEST('07 Excess'!E$8:E$127,'05 Factors'!C$8:E$127,TRUE,TRUE),5,2)/INDEX(LINEST('07 Excess'!E$8:E$127,'05 Factors'!C$8:E$127,TRUE,TRUE),4,2) -> 0.0012878351 | H11: =COUNT('07 Excess'!E$8:E$127) -> 120 | I11: =INDEX(LINEST('07 Excess'!E$8:E$127,'05 Factors'!C$8:E$127,TRUE,TRUE),2,4) -> 0.0034043428
A12: NVDA | B12: =INDEX(LINEST('07 Excess'!F$8:F$127,'05 Factors'!C$8:E$127,TRUE,TRUE),1,4) -> 0.032944034 | C12: =INDEX(LINEST('07 Excess'!F$8:F$127,'05 Factors'!C$8:E$127,TRUE,TRUE),1,3) -> 1.8544484 | D12: =INDEX(LINEST('07 Excess'!F$8:F$127,'05 Factors'!C$8:E$127,TRUE,TRUE),1,2) -> -0.22175806 | E12: =INDEX(LINEST('07 Excess'!F$8:F$127,'05 Factors'!C$8:E$127,TRUE,TRUE),1,1) -> -1.0471048 | F12: =INDEX(LINEST('07 Excess'!F$8:F$127,'05 Factors'!C$8:E$127,TRUE,TRUE),3,1) -> 0.44707975 | G12: =INDEX(LINEST('07 Excess'!F$8:F$127,'05 Factors'!C$8:E$127,TRUE,TRUE),5,2)/INDEX(LINEST('07 Excess'!F$8:F$127,'05 Factors'!C$8:E$127,TRUE,TRUE),4,2) -> 0.010647515 | H12: =COUNT('07 Excess'!F$8:F$127) -> 120 | I12: =INDEX(LINEST('07 Excess'!F$8:F$127,'05 Factors'!C$8:E$127,TRUE,TRUE),2,4) -> 0.0097887513
A13: PFE | B13: =INDEX(LINEST('07 Excess'!G$8:G$127,'05 Factors'!C$8:E$127,TRUE,TRUE),1,4) -> -0.0047813121 | C13: =INDEX(LINEST('07 Excess'!G$8:G$127,'05 Factors'!C$8:E$127,TRUE,TRUE),1,3) -> 0.59981781 | D13: =INDEX(LINEST('07 Excess'!G$8:G$127,'05 Factors'!C$8:E$127,TRUE,TRUE),1,2) -> -0.30467488 | E13: =INDEX(LINEST('07 Excess'!G$8:G$127,'05 Factors'!C$8:E$127,TRUE,TRUE),1,1) -> 0.12493653 | F13: =INDEX(LINEST('07 Excess'!G$8:G$127,'05 Factors'!C$8:E$127,TRUE,TRUE),3,1) -> 0.15879094 | G13: =INDEX(LINEST('07 Excess'!G$8:G$127,'05 Factors'!C$8:E$127,TRUE,TRUE),5,2)/INDEX(LINEST('07 Excess'!G$8:G$127,'05 Factors'!C$8:E$127,TRUE,TRUE),4,2) -> 0.0036835588 | H13: =COUNT('07 Excess'!G$8:G$127) -> 120 | I13: =INDEX(LINEST('07 Excess'!G$8:G$127,'05 Factors'!C$8:E$127,TRUE,TRUE),2,4) -> 0.00575754
A14: TGT | B14: =INDEX(LINEST('07 Excess'!H$8:H$127,'05 Factors'!C$8:E$127,TRUE,TRUE),1,4) -> -0.0037732117 | C14: =INDEX(LINEST('07 Excess'!H$8:H$127,'05 Factors'!C$8:E$127,TRUE,TRUE),1,3) -> 1.0146258 | D14: =INDEX(LINEST('07 Excess'!H$8:H$127,'05 Factors'!C$8:E$127,TRUE,TRUE),1,2) -> 0.027656325 | E14: =INDEX(LINEST('07 Excess'!H$8:H$127,'05 Factors'!C$8:E$127,TRUE,TRUE),1,1) -> -0.063623733 | F14: =INDEX(LINEST('07 Excess'!H$8:H$127,'05 Factors'!C$8:E$127,TRUE,TRUE),3,1) -> 0.27007728 | G14: =INDEX(LINEST('07 Excess'!H$8:H$127,'05 Factors'!C$8:E$127,TRUE,TRUE),5,2)/INDEX(LINEST('07 Excess'!H$8:H$127,'05 Factors'!C$8:E$127,TRUE,TRUE),4,2) -> 0.0059679629 | H14: =COUNT('07 Excess'!H$8:H$127) -> 120 | I14: =INDEX(LINEST('07 Excess'!H$8:H$127,'05 Factors'!C$8:E$127,TRUE,TRUE),2,4) -> 0.007328519
A15: XOM | B15: =INDEX(LINEST('07 Excess'!I$8:I$127,'05 Factors'!C$8:E$127,TRUE,TRUE),1,4) -> -2.5703588e-05 | C15: =INDEX(LINEST('07 Excess'!I$8:I$127,'05 Factors'!C$8:E$127,TRUE,TRUE),1,3) -> 0.83669036 | D15: =INDEX(LINEST('07 Excess'!I$8:I$127,'05 Factors'!C$8:E$127,TRUE,TRUE),1,2) -> 0.0061999245 | E15: =INDEX(LINEST('07 Excess'!I$8:I$127,'05 Factors'!C$8:E$127,TRUE,TRUE),1,1) -> 1.033559 | F15: =INDEX(LINEST('07 Excess'!I$8:I$127,'05 Factors'!C$8:E$127,TRUE,TRUE),3,1) -> 0.49640306 | G15: =INDEX(LINEST('07 Excess'!I$8:I$127,'05 Factors'!C$8:E$127,TRUE,TRUE),5,2)/INDEX(LINEST('07 Excess'!I$8:I$127,'05 Factors'!C$8:E$127,TRUE,TRUE),4,2) -> 0.0031871658 | H15: =COUNT('07 Excess'!I$8:I$127) -> 120 | I15: =INDEX(LINEST('07 Excess'!I$8:I$127,'05 Factors'!C$8:E$127,TRUE,TRUE),2,4) -> 0.0053555675
A16: WMT | B16: =INDEX(LINEST('07 Excess'!J$8:J$127,'05 Factors'!C$8:E$127,TRUE,TRUE),1,4) -> 0.0079811433 | C16: =INDEX(LINEST('07 Excess'!J$8:J$127,'05 Factors'!C$8:E$127,TRUE,TRUE),1,3) -> 0.60032002 | D16: =INDEX(LINEST('07 Excess'!J$8:J$127,'05 Factors'!C$8:E$127,TRUE,TRUE),1,2) -> -0.53147711 | E16: =INDEX(LINEST('07 Excess'!J$8:J$127,'05 Factors'!C$8:E$127,TRUE,TRUE),1,1) -> -0.1528714 | F16: =INDEX(LINEST('07 Excess'!J$8:J$127,'05 Factors'!C$8:E$127,TRUE,TRUE),3,1) -> 0.26125263 | G16: =INDEX(LINEST('07 Excess'!J$8:J$127,'05 Factors'!C$8:E$127,TRUE,TRUE),5,2)/INDEX(LINEST('07 Excess'!J$8:J$127,'05 Factors'!C$8:E$127,TRUE,TRUE),4,2) -> 0.0021383058 | H16: =COUNT('07 Excess'!J$8:J$127) -> 120 | I16: =INDEX(LINEST('07 Excess'!J$8:J$127,'05 Factors'!C$8:E$127,TRUE,TRUE),2,4) -> 0.0043867014
A17: VZ | B17: =INDEX(LINEST('07 Excess'!K$8:K$127,'05 Factors'!C$8:E$127,TRUE,TRUE),1,4) -> -0.0026962839 | C17: =INDEX(LINEST('07 Excess'!K$8:K$127,'05 Factors'!C$8:E$127,TRUE,TRUE),1,3) -> 0.43713806 | D17: =INDEX(LINEST('07 Excess'!K$8:K$127,'05 Factors'!C$8:E$127,TRUE,TRUE),1,2) -> -0.56725463 | E17: =INDEX(LINEST('07 Excess'!K$8:K$127,'05 Factors'!C$8:E$127,TRUE,TRUE),1,1) -> 0.25717329 | F17: =INDEX(LINEST('07 Excess'!K$8:K$127,'05 Factors'!C$8:E$127,TRUE,TRUE),3,1) -> 0.18774557 | G17: =INDEX(LINEST('07 Excess'!K$8:K$127,'05 Factors'!C$8:E$127,TRUE,TRUE),5,2)/INDEX(LINEST('07 Excess'!K$8:K$127,'05 Factors'!C$8:E$127,TRUE,TRUE),4,2) -> 0.0022457438 | H17: =COUNT('07 Excess'!K$8:K$127) -> 120 | I17: =INDEX(LINEST('07 Excess'!K$8:K$127,'05 Factors'!C$8:E$127,TRUE,TRUE),2,4) -> 0.0044955545
A21: How to recreate this output in Excel
A22: 1. Use stock excess returns on 07 Excess as Y and '05 Factors'!C8:E127 as X.
A23: 2. LINEST(Y,X,TRUE,TRUE) estimates 3 factor coefficients and an intercept. INDEX selects individual results, so use ordinary Enter.
A24: 3. LINEST returns slopes in reverse X-column order, followed by the intercept. This table restores the original factor order.
A25: 4. Alpha = INDEX(LINEST(Y,X,TRUE,TRUE),1,4). Its standard error is in row 2 of the LINEST result, in the same column.
A26: 5. Residual variance = residual sum of squares / degrees of freedom, or SSE/(N - number of factors - 1).
A27: 6. Alternative: Data > Data Analysis > Regression; select the same Y and X ranges and leave Constant is Zero unchecked.
A28: 7. Positive alpha alone does not establish skill. Compare model definitions and sampling uncertainty; Alpha SE measures that uncertainty.

Sheet 10 Carhart4
A1: Carhart | four factors
A2: Back to guide
A3: Same 120 monthly observations for every asset. LINEST includes an intercept. Alpha and its standard error are monthly.
A7: Asset | B7: Monthly alpha | C7: MKT | D7: SMB | E7: HML | F7: MOM | G7: R-squared | H7: Residual variance | I7: N | J7: Alpha SE
A8: AMD | B8: =INDEX(LINEST('07 Excess'!B$8:B$127,'05 Factors'!C$8:F$127,TRUE,TRUE),1,5) -> 0.025168731 | C8: =INDEX(LINEST('07 Excess'!B$8:B$127,'05 Factors'!C$8:F$127,TRUE,TRUE),1,4) -> 2.0658608 | D8: =INDEX(LINEST('07 Excess'!B$8:B$127,'05 Factors'!C$8:F$127,TRUE,TRUE),1,3) -> -0.23655235 | E8: =INDEX(LINEST('07 Excess'!B$8:B$127,'05 Factors'!C$8:F$127,TRUE,TRUE),1,2) -> -1.0436577 | F8: =INDEX(LINEST('07 Excess'!B$8:B$127,'05 Factors'!C$8:F$127,TRUE,TRUE),1,1) -> -0.10655989 | G8: =INDEX(LINEST('07 Excess'!B$8:B$127,'05 Factors'!C$8:F$127,TRUE,TRUE),3,1) -> 0.35544214 | H8: =INDEX(LINEST('07 Excess'!B$8:B$127,'05 Factors'!C$8:F$127,TRUE,TRUE),5,2)/INDEX(LINEST('07 Excess'!B$8:B$127,'05 Factors'!C$8:F$127,TRUE,TRUE),4,2) -> 0.019173938 | I8: =COUNT('07 Excess'!B$8:B$127) -> 120 | J8: =INDEX(LINEST('07 Excess'!B$8:B$127,'05 Factors'!C$8:F$127,TRUE,TRUE),2,5) -> 0.013164094
A9: AMZN | B9: =INDEX(LINEST('07 Excess'!C$8:C$127,'05 Factors'!C$8:F$127,TRUE,TRUE),1,5) -> 0.0042701507 | C9: =INDEX(LINEST('07 Excess'!C$8:C$127,'05 Factors'!C$8:F$127,TRUE,TRUE),1,4) -> 1.2244309 | D9: =INDEX(LINEST('07 Excess'!C$8:C$127,'05 Factors'!C$8:F$127,TRUE,TRUE),1,3) -> -0.11337165 | E9: =INDEX(LINEST('07 Excess'!C$8:C$127,'05 Factors'!C$8:F$127,TRUE,TRUE),1,2) -> -0.98635083 | F9: =INDEX(LINEST('07 Excess'!C$8:C$127,'05 Factors'!C$8:F$127,TRUE,TRUE),1,1) -> -0.17327485 | G9: =INDEX(LINEST('07 Excess'!C$8:C$127,'05 Factors'!C$8:F$127,TRUE,TRUE),3,1) -> 0.61262239 | H9: =INDEX(LINEST('07 Excess'!C$8:C$127,'05 Factors'!C$8:F$127,TRUE,TRUE),5,2)/INDEX(LINEST('07 Excess'!C$8:C$127,'05 Factors'!C$8:F$127,TRUE,TRUE),4,2) -> 0.0029893489 | I9: =COUNT('07 Excess'!C$8:C$127) -> 120 | J9: =INDEX(LINEST('07 Excess'!C$8:C$127,'05 Factors'!C$8:F$127,TRUE,TRUE),2,5) -> 0.0051978485
A10: F | B10: =INDEX(LINEST('07 Excess'!D$8:D$127,'05 Factors'!C$8:F$127,TRUE,TRUE),1,5) -> -0.0053572733 | C10: =INDEX(LINEST('07 Excess'!D$8:D$127,'05 Factors'!C$8:F$127,TRUE,TRUE),1,4) -> 1.2675451 | D10: =INDEX(LINEST('07 Excess'!D$8:D$127,'05 Factors'!C$8:F$127,TRUE,TRUE),1,3) -> 0.32243755 | E10: =INDEX(LINEST('07 Excess'!D$8:D$127,'05 Factors'!C$8:F$127,TRUE,TRUE),1,2) -> 0.48650569 | F10: =INDEX(LINEST('07 Excess'!D$8:D$127,'05 Factors'!C$8:F$127,TRUE,TRUE),1,1) -> -0.2305012 | G10: =INDEX(LINEST('07 Excess'!D$8:D$127,'05 Factors'!C$8:F$127,TRUE,TRUE),3,1) -> 0.45291888 | H10: =INDEX(LINEST('07 Excess'!D$8:D$127,'05 Factors'!C$8:F$127,TRUE,TRUE),5,2)/INDEX(LINEST('07 Excess'!D$8:D$127,'05 Factors'!C$8:F$127,TRUE,TRUE),4,2) -> 0.0059630961 | I10: =COUNT('07 Excess'!D$8:D$127) -> 120 | J10: =INDEX(LINEST('07 Excess'!D$8:D$127,'05 Factors'!C$8:F$127,TRUE,TRUE),2,5) -> 0.0073412703
A11: JPM | B11: =INDEX(LINEST('07 Excess'!E$8:E$127,'05 Factors'!C$8:F$127,TRUE,TRUE),1,5) -> 0.0043508649 | C11: =INDEX(LINEST('07 Excess'!E$8:E$127,'05 Factors'!C$8:F$127,TRUE,TRUE),1,4) -> 1.149796 | D11: =INDEX(LINEST('07 Excess'!E$8:E$127,'05 Factors'!C$8:F$127,TRUE,TRUE),1,3) -> 0.098721668 | E11: =INDEX(LINEST('07 Excess'!E$8:E$127,'05 Factors'!C$8:F$127,TRUE,TRUE),1,2) -> 0.86364041 | F11: =INDEX(LINEST('07 Excess'!E$8:E$127,'05 Factors'!C$8:F$127,TRUE,TRUE),1,1) -> 0.14556407 | G11: =INDEX(LINEST('07 Excess'!E$8:E$127,'05 Factors'!C$8:F$127,TRUE,TRUE),3,1) -> 0.74845144 | H11: =INDEX(LINEST('07 Excess'!E$8:E$127,'05 Factors'!C$8:F$127,TRUE,TRUE),5,2)/INDEX(LINEST('07 Excess'!E$8:E$127,'05 Factors'!C$8:F$127,TRUE,TRUE),4,2) -> 0.0012762593 | I11: =COUNT('07 Excess'!E$8:E$127) -> 120 | J11: =INDEX(LINEST('07 Excess'!E$8:E$127,'05 Factors'!C$8:F$127,TRUE,TRUE),2,5) -> 0.00339629
A12: NVDA | B12: =INDEX(LINEST('07 Excess'!F$8:F$127,'05 Factors'!C$8:F$127,TRUE,TRUE),1,5) -> 0.032632362 | C12: =INDEX(LINEST('07 Excess'!F$8:F$127,'05 Factors'!C$8:F$127,TRUE,TRUE),1,4) -> 1.8894402 | D12: =INDEX(LINEST('07 Excess'!F$8:F$127,'05 Factors'!C$8:F$127,TRUE,TRUE),1,3) -> -0.1691491 | E12: =INDEX(LINEST('07 Excess'!F$8:F$127,'05 Factors'!C$8:F$127,TRUE,TRUE),1,2) -> -1.0078316 | F12: =INDEX(LINEST('07 Excess'!F$8:F$127,'05 Factors'!C$8:F$127,TRUE,TRUE),1,1) -> 0.14247704 | G12: =INDEX(LINEST('07 Excess'!F$8:F$127,'05 Factors'!C$8:F$127,TRUE,TRUE),3,1) -> 0.44820301 | H12: =INDEX(LINEST('07 Excess'!F$8:F$127,'05 Factors'!C$8:F$127,TRUE,TRUE),5,2)/INDEX(LINEST('07 Excess'!F$8:F$127,'05 Factors'!C$8:F$127,TRUE,TRUE),4,2) -> 0.010718283 | I12: =COUNT('07 Excess'!F$8:F$127) -> 120 | J12: =INDEX(LINEST('07 Excess'!F$8:F$127,'05 Factors'!C$8:F$127,TRUE,TRUE),2,5) -> 0.0098423301
A13: PFE | B13: =INDEX(LINEST('07 Excess'!G$8:G$127,'05 Factors'!C$8:F$127,TRUE,TRUE),1,5) -> -0.0051866756 | C13: =INDEX(LINEST('07 Excess'!G$8:G$127,'05 Factors'!C$8:F$127,TRUE,TRUE),1,4) -> 0.64532862 | D13: =INDEX(LINEST('07 Excess'!G$8:G$127,'05 Factors'!C$8:F$127,TRUE,TRUE),1,3) -> -0.23625103 | E13: =INDEX(LINEST('07 Excess'!G$8:G$127,'05 Factors'!C$8:F$127,TRUE,TRUE),1,2) -> 0.17601576 | F13: =INDEX(LINEST('07 Excess'!G$8:G$127,'05 Factors'!C$8:F$127,TRUE,TRUE),1,1) -> 0.18530736 | G13: =INDEX(LINEST('07 Excess'!G$8:G$127,'05 Factors'!C$8:F$127,TRUE,TRUE),3,1) -> 0.16714695 | H13: =INDEX(LINEST('07 Excess'!G$8:G$127,'05 Factors'!C$8:F$127,TRUE,TRUE),5,2)/INDEX(LINEST('07 Excess'!G$8:G$127,'05 Factors'!C$8:F$127,TRUE,TRUE),4,2) -> 0.0036786815 | I13: =COUNT('07 Excess'!G$8:G$127) -> 120 | J13: =INDEX(LINEST('07 Excess'!G$8:G$127,'05 Factors'!C$8:F$127,TRUE,TRUE),2,5) -> 0.0057660899
A14: TGT | B14: =INDEX(LINEST('07 Excess'!H$8:H$127,'05 Factors'!C$8:F$127,TRUE,TRUE),1,5) -> -0.0038280305 | C14: =INDEX(LINEST('07 Excess'!H$8:H$127,'05 Factors'!C$8:F$127,TRUE,TRUE),1,4) -> 1.0207804 | D14: =INDEX(LINEST('07 Excess'!H$8:H$127,'05 Factors'!C$8:F$127,TRUE,TRUE),1,3) -> 0.036909545 | E14: =INDEX(LINEST('07 Excess'!H$8:H$127,'05 Factors'!C$8:F$127,TRUE,TRUE),1,2) -> -0.056716092 | F14: =INDEX(LINEST('07 Excess'!H$8:H$127,'05 Factors'!C$8:F$127,TRUE,TRUE),1,1) -> 0.025059827 | G14: =INDEX(LINEST('07 Excess'!H$8:H$127,'05 Factors'!C$8:F$127,TRUE,TRUE),3,1) -> 0.27015912 | H14: =INDEX(LINEST('07 Excess'!H$8:H$127,'05 Factors'!C$8:F$127,TRUE,TRUE),5,2)/INDEX(LINEST('07 Excess'!H$8:H$127,'05 Factors'!C$8:F$127,TRUE,TRUE),4,2) -> 0.0060191832 | I14: =COUNT('07 Excess'!H$8:H$127) -> 120 | J14: =INDEX(LINEST('07 Excess'!H$8:H$127,'05 Factors'!C$8:F$127,TRUE,TRUE),2,5) -> 0.0073757144
A15: XOM | B15: =INDEX(LINEST('07 Excess'!I$8:I$127,'05 Factors'!C$8:F$127,TRUE,TRUE),1,5) -> 0.00020841809 | C15: =INDEX(LINEST('07 Excess'!I$8:I$127,'05 Factors'!C$8:F$127,TRUE,TRUE),1,4) -> 0.81040515 | D15: =INDEX(LINEST('07 Excess'!I$8:I$127,'05 Factors'!C$8:F$127,TRUE,TRUE),1,3) -> -0.033318937 | E15: =INDEX(LINEST('07 Excess'!I$8:I$127,'05 Factors'!C$8:F$127,TRUE,TRUE),1,2) -> 1.0040577 | F15: =INDEX(LINEST('07 Excess'!I$8:I$127,'05 Factors'!C$8:F$127,TRUE,TRUE),1,1) -> -0.10702607 | G15: =INDEX(LINEST('07 Excess'!I$8:I$127,'05 Factors'!C$8:F$127,TRUE,TRUE),3,1) -> 0.49833163 | H15: =INDEX(LINEST('07 Excess'!I$8:I$127,'05 Factors'!C$8:F$127,TRUE,TRUE),5,2)/INDEX(LINEST('07 Excess'!I$8:I$127,'05 Factors'!C$8:F$127,TRUE,TRUE),4,2) -> 0.0032025687 | I15: =COUNT('07 Excess'!I$8:I$127) -> 120 | J15: =INDEX(LINEST('07 Excess'!I$8:I$127,'05 Factors'!C$8:F$127,TRUE,TRUE),2,5) -> 0.005380028
A16: WMT | B16: =INDEX(LINEST('07 Excess'!J$8:J$127,'05 Factors'!C$8:F$127,TRUE,TRUE),1,5) -> 0.0075944024 | C16: =INDEX(LINEST('07 Excess'!J$8:J$127,'05 Factors'!C$8:F$127,TRUE,TRUE),1,4) -> 0.64374003 | D16: =INDEX(LINEST('07 Excess'!J$8:J$127,'05 Factors'!C$8:F$127,TRUE,TRUE),1,3) -> -0.46619669 | E16: =INDEX(LINEST('07 Excess'!J$8:J$127,'05 Factors'!C$8:F$127,TRUE,TRUE),1,2) -> -0.10413878 | F16: =INDEX(LINEST('07 Excess'!J$8:J$127,'05 Factors'!C$8:F$127,TRUE,TRUE),1,1) -> 0.17679422 | G16: =INDEX(LINEST('07 Excess'!J$8:J$127,'05 Factors'!C$8:F$127,TRUE,TRUE),3,1) -> 0.27275903 | H16: =INDEX(LINEST('07 Excess'!J$8:J$127,'05 Factors'!C$8:F$127,TRUE,TRUE),5,2)/INDEX(LINEST('07 Excess'!J$8:J$127,'05 Factors'!C$8:F$127,TRUE,TRUE),4,2) -> 0.0021233049 | I16: =COUNT('07 Excess'!J$8:J$127) -> 120 | J16: =INDEX(LINEST('07 Excess'!J$8:J$127,'05 Factors'!C$8:F$127,TRUE,TRUE),2,5) -> 0.0043806796
A17: VZ | B17: =INDEX(LINEST('07 Excess'!K$8:K$127,'05 Factors'!C$8:F$127,TRUE,TRUE),1,5) -> -0.0025324156 | C17: =INDEX(LINEST('07 Excess'!K$8:K$127,'05 Factors'!C$8:F$127,TRUE,TRUE),1,4) -> 0.4187403 | D17: =INDEX(LINEST('07 Excess'!K$8:K$127,'05 Factors'!C$8:F$127,TRUE,TRUE),1,3) -> -0.59491499 | E17: =INDEX(LINEST('07 Excess'!K$8:K$127,'05 Factors'!C$8:F$127,TRUE,TRUE),1,2) -> 0.2365245 | F17: =INDEX(LINEST('07 Excess'!K$8:K$127,'05 Factors'!C$8:F$127,TRUE,TRUE),1,1) -> -0.074910556 | G17: =INDEX(LINEST('07 Excess'!K$8:K$127,'05 Factors'!C$8:F$127,TRUE,TRUE),3,1) -> 0.18990827 | H17: =INDEX(LINEST('07 Excess'!K$8:K$127,'05 Factors'!C$8:F$127,TRUE,TRUE),5,2)/INDEX(LINEST('07 Excess'!K$8:K$127,'05 Factors'!C$8:F$127,TRUE,TRUE),4,2) -> 0.0022592405 | I17: =COUNT('07 Excess'!K$8:K$127) -> 120 | J17: =INDEX(LINEST('07 Excess'!K$8:K$127,'05 Factors'!C$8:F$127,TRUE,TRUE),2,5) -> 0.0045187316
A21: How to recreate this output in Excel
A22: 1. Use stock excess returns on 07 Excess as Y and '05 Factors'!C8:F127 as X.
A23: 2. LINEST(Y,X,TRUE,TRUE) estimates 4 factor coefficients and an intercept. INDEX selects individual results, so use ordinary Enter.
A24: 3. LINEST returns slopes in reverse X-column order, followed by the intercept. This table restores the original factor order.
A25: 4. Alpha = INDEX(LINEST(Y,X,TRUE,TRUE),1,5). Its standard error is in row 2 of the LINEST result, in the same column.
A26: 5. Residual variance = residual sum of squares / degrees of freedom, or SSE/(N - number of factors - 1).
A27: 6. Alternative: Data > Data Analysis > Regression; select the same Y and X ranges and leave Constant is Zero unchecked.
A28: 7. Positive alpha alone does not establish skill. Compare model definitions and sampling uncertainty; Alpha SE measures that uncertainty.

Sheet 11 FF5
A1: Fama-French | five factors
A2: Back to guide
A3: Same 120 monthly observations for every asset. LINEST includes an intercept. Alpha and its standard error are monthly.
A7: Asset | B7: Monthly alpha | C7: MKT | D7: SMB | E7: HML | F7: RMW | G7: CMA | H7: R-squared | I7: Residual variance | J7: N | K7: Alpha SE
A8: AMD | B8: =INDEX(LINEST('07 Excess'!B$8:B$127,'05 Factors'!G$8:K$127,TRUE,TRUE),1,6) -> 0.026199775 | C8: =INDEX(LINEST('07 Excess'!B$8:B$127,'05 Factors'!G$8:K$127,TRUE,TRUE),1,5) -> 2.1846123 | D8: =INDEX(LINEST('07 Excess'!B$8:B$127,'05 Factors'!G$8:K$127,TRUE,TRUE),1,4) -> -0.673746 | E8: =INDEX(LINEST('07 Excess'!B$8:B$127,'05 Factors'!G$8:K$127,TRUE,TRUE),1,3) -> -0.71614872 | F8: =INDEX(LINEST('07 Excess'!B$8:B$127,'05 Factors'!G$8:K$127,TRUE,TRUE),1,2) -> -1.0506867 | G8: =INDEX(LINEST('07 Excess'!B$8:B$127,'05 Factors'!G$8:K$127,TRUE,TRUE),1,1) -> -0.10895126 | H8: =INDEX(LINEST('07 Excess'!B$8:B$127,'05 Factors'!G$8:K$127,TRUE,TRUE),3,1) -> 0.37118146 | I8: =INDEX(LINEST('07 Excess'!B$8:B$127,'05 Factors'!G$8:K$127,TRUE,TRUE),5,2)/INDEX(LINEST('07 Excess'!B$8:B$127,'05 Factors'!G$8:K$127,TRUE,TRUE),4,2) -> 0.01886982 | J8: =COUNT('07 Excess'!B$8:B$127) -> 120 | K8: =INDEX(LINEST('07 Excess'!B$8:B$127,'05 Factors'!G$8:K$127,TRUE,TRUE),2,6) -> 0.013084902
A9: AMZN | B9: =INDEX(LINEST('07 Excess'!C$8:C$127,'05 Factors'!G$8:K$127,TRUE,TRUE),1,6) -> 0.0049182697 | C9: =INDEX(LINEST('07 Excess'!C$8:C$127,'05 Factors'!G$8:K$127,TRUE,TRUE),1,5) -> 1.2656001 | D9: =INDEX(LINEST('07 Excess'!C$8:C$127,'05 Factors'!G$8:K$127,TRUE,TRUE),1,4) -> -0.39880531 | E9: =INDEX(LINEST('07 Excess'!C$8:C$127,'05 Factors'!G$8:K$127,TRUE,TRUE),1,3) -> -0.52325098 | F9: =INDEX(LINEST('07 Excess'!C$8:C$127,'05 Factors'!G$8:K$127,TRUE,TRUE),1,2) -> -0.62449845 | G9: =INDEX(LINEST('07 Excess'!C$8:C$127,'05 Factors'!G$8:K$127,TRUE,TRUE),1,1) -> -0.64963987 | H9: =INDEX(LINEST('07 Excess'!C$8:C$127,'05 Factors'!G$8:K$127,TRUE,TRUE),3,1) -> 0.65109281 | I9: =INDEX(LINEST('07 Excess'!C$8:C$127,'05 Factors'!G$8:K$127,TRUE,TRUE),5,2)/INDEX(LINEST('07 Excess'!C$8:C$127,'05 Factors'!G$8:K$127,TRUE,TRUE),4,2) -> 0.0027160953 | J9: =COUNT('07 Excess'!C$8:C$127) -> 120 | K9: =INDEX(LINEST('07 Excess'!C$8:C$127,'05 Factors'!G$8:K$127,TRUE,TRUE),2,6) -> 0.0049643125
A10: F | B10: =INDEX(LINEST('07 Excess'!D$8:D$127,'05 Factors'!G$8:K$127,TRUE,TRUE),1,6) -> -0.0058918014 | C10: =INDEX(LINEST('07 Excess'!D$8:D$127,'05 Factors'!G$8:K$127,TRUE,TRUE),1,5) -> 1.2950496 | D10: =INDEX(LINEST('07 Excess'!D$8:D$127,'05 Factors'!G$8:K$127,TRUE,TRUE),1,4) -> 0.32269382 | E10: =INDEX(LINEST('07 Excess'!D$8:D$127,'05 Factors'!G$8:K$127,TRUE,TRUE),1,3) -> 0.62803898 | F10: =INDEX(LINEST('07 Excess'!D$8:D$127,'05 Factors'!G$8:K$127,TRUE,TRUE),1,2) -> 0.023310904 | G10: =INDEX(LINEST('07 Excess'!D$8:D$127,'05 Factors'!G$8:K$127,TRUE,TRUE),1,1) -> -0.34956534 | H10: =INDEX(LINEST('07 Excess'!D$8:D$127,'05 Factors'!G$8:K$127,TRUE,TRUE),3,1) -> 0.448717 | I10: =INDEX(LINEST('07 Excess'!D$8:D$127,'05 Factors'!G$8:K$127,TRUE,TRUE),5,2)/INDEX(LINEST('07 Excess'!D$8:D$127,'05 Factors'!G$8:K$127,TRUE,TRUE),4,2) -> 0.0060616056 | J10: =COUNT('07 Excess'!D$8:D$127) -> 120 | K10: =INDEX(LINEST('07 Excess'!D$8:D$127,'05 Factors'!G$8:K$127,TRUE,TRUE),2,6) -> 0.0074161832
